2025-09-06 20:31:18,246 - INFO - üìÑ Log file: output\logs\experiment_log_month_1_20250906_203118.txt
2025-09-06 20:31:18,246 - INFO - üîç Checking requirements...
2025-09-06 20:31:18,246 - INFO - üìã LLM Provider: google
2025-09-06 20:31:18,246 - INFO - ‚úÖ Google API Key found: AIzaSyDDV3...
2025-09-06 20:31:27,287 - INFO - ‚úÖ crewai is installed
2025-09-06 20:31:27,304 - INFO - ‚úÖ langchain is installed
2025-09-06 20:31:27,870 - INFO - ‚úÖ pandas is installed
2025-09-06 20:31:27,870 - INFO - ‚úÖ python-dotenv is installed
2025-09-06 20:31:27,870 - INFO - ‚úÖ All required packages are installed
2025-09-06 20:31:27,870 - INFO - ‚úÖ Using GOOGLE as LLM provider
2025-09-06 20:31:27,870 - INFO - üîë Set Google Gemini API key for CrewAI compatibility
2025-09-06 20:31:27,870 - INFO - üì¶ Importing experiment modules...
2025-09-06 20:31:27,905 - INFO - üèóÔ∏è  Creating experiment instance...
2025-09-06 20:31:27,905 - INFO - ‚úÖ Experiment instance created successfully
2025-09-06 20:31:27,912 - INFO - ‚öôÔ∏è  Setting up crew...
2025-09-06 20:31:58,534 - INFO - Anonymized telemetry enabled. See                     https://docs.trychroma.com/telemetry for more information.
2025-09-06 20:31:58,798 - INFO - Collection found or created: Collection(name=short_term)
2025-09-06 20:31:59,087 - INFO - Anonymized telemetry enabled. See                     https://docs.trychroma.com/telemetry for more information.
2025-09-06 20:31:59,188 - INFO - Collection found or created: Collection(name=entities)
2025-09-06 20:31:59,198 - INFO - ‚úÖ Crew setup completed
2025-09-06 20:31:59,198 - INFO - üöÄ Starting Month 1 execution...
2025-09-06 20:31:59,198 - INFO - ------------------------------------------------------------
2025-09-06 20:31:59,198 - INFO - üöÄ Running Month 1 of MAS Family Inheritance Experiment
2025-09-06 20:31:59,198 - INFO - ============================================================
2025-09-06 20:31:59,198 - INFO - ü§ñ Using LLM Provider: GOOGLE
2025-09-06 20:31:59,198 - INFO - üìù Model: gemini-1.5-flash
2025-09-06 20:31:59,198 - INFO - ‚è≥ Rate Limiting: 8 requests/minute, 80 requests/hour (conservative limits)
2025-09-06 20:31:59,198 - INFO - ============================================================
2025-09-06 20:31:59,198 - INFO - üîß Configured CrewAI to use Google Gemini
2025-09-06 20:31:59,198 - INFO - üîë Set Google Gemini API key for CrewAI compatibility
2025-09-06 20:31:59,198 - INFO - 
üìÖ Starting Month 1
2025-09-06 20:31:59,198 - INFO - ----------------------------------------
2025-09-06 20:31:59,198 - INFO - üìã Found 2 events for Month 1
2025-09-06 20:31:59,198 - INFO - üîÑ Running scenario: The Inheritance
2025-09-06 20:31:59,198 - INFO - 
============================================================
2025-09-06 20:31:59,198 - INFO - Running Scenario: The Inheritance
2025-09-06 20:31:59,198 - INFO - Month 1, Week 1
2025-09-06 20:31:59,198 - INFO - ============================================================
2025-09-06 20:32:27,997 - INFO - üöÄ Starting CrewAI task execution...
2025-09-06 20:32:28,359 - ERROR - Error during short_term search: APIStatusError.__init__() missing 2 required keyword-only arguments: 'response' and 'body'
2025-09-06 20:32:28,603 - ERROR - Error during entities search: APIStatusError.__init__() missing 2 required keyword-only arguments: 'response' and 'body'
2025-09-06 20:32:28,630 - INFO - 
LiteLLM completion() model= gemini-1.5-flash; provider = gemini
2025-09-06 20:32:38,388 - INFO - Wrapper: Completed Call, calling success_handler
2025-09-06 20:32:38,605 - ERROR - Error during short_term save: APIStatusError.__init__() missing 2 required keyword-only arguments: 'response' and 'body'
2025-09-06 20:32:40,087 - INFO - 
LiteLLM completion() model= gemini-1.5-flash; provider = gemini
2025-09-06 20:32:40,977 - INFO - Wrapper: Completed Call, calling success_handler
2025-09-06 20:32:41,236 - ERROR - Error during short_term search: APIStatusError.__init__() missing 2 required keyword-only arguments: 'response' and 'body'
2025-09-06 20:32:41,488 - ERROR - Error during entities search: APIStatusError.__init__() missing 2 required keyword-only arguments: 'response' and 'body'
2025-09-06 20:32:41,505 - INFO - 
LiteLLM completion() model= gemini-1.5-flash; provider = gemini
2025-09-06 20:32:41,959 - ERROR - Error during short_term search: APIStatusError.__init__() missing 2 required keyword-only arguments: 'response' and 'body'
2025-09-06 20:32:42,153 - ERROR - Error during entities search: APIStatusError.__init__() missing 2 required keyword-only arguments: 'response' and 'body'
2025-09-06 20:32:42,161 - INFO - 
LiteLLM completion() model= gemini-1.5-flash; provider = gemini
2025-09-06 20:32:42,953 - ERROR - Error during short_term search: APIStatusError.__init__() missing 2 required keyword-only arguments: 'response' and 'body'
2025-09-06 20:32:43,138 - ERROR - Error during entities search: APIStatusError.__init__() missing 2 required keyword-only arguments: 'response' and 'body'
2025-09-06 20:32:43,159 - INFO - 
LiteLLM completion() model= gemini-1.5-flash; provider = gemini
2025-09-06 20:32:43,434 - ERROR - ‚ùå Experiment failed: Task execution failed: litellm.RateLimitError: litellm.RateLimitError: VertexAIException - {
  "error": {
    "code": 429,
    "message": "You exceeded your current quota, please check your plan and billing details. For more information on this error, head to: https://ai.google.dev/gemini-api/docs/rate-limits.",
    "status": "RESOURCE_EXHAUSTED",
    "details": [
      {
        "@type": "type.googleapis.com/google.rpc.QuotaFailure",
        "violations": [
          {
            "quotaMetric": "generativelanguage.googleapis.com/generate_content_free_tier_requests",
            "quotaId": "GenerateRequestsPerDayPerProjectPerModel-FreeTier",
            "quotaDimensions": {
              "location": "global",
              "model": "gemini-1.5-flash"
            },
            "quotaValue": "50"
          }
        ]
      },
      {
        "@type": "type.googleapis.com/google.rpc.Help",
        "links": [
          {
            "description": "Learn more about Gemini API quotas",
            "url": "https://ai.google.dev/gemini-api/docs/rate-limits"
          }
        ]
      },
      {
        "@type": "type.googleapis.com/google.rpc.RetryInfo",
        "retryDelay": "15s"
      }
    ]
  }
}

2025-09-06 20:32:43,436 - ERROR - Full error details:
2025-09-06 20:32:43,446 - ERROR - Traceback (most recent call last):
  File "C:\Users\AngelicaChowdhury\anaconda3\envs\mas_family_exp\lib\site-packages\litellm\llms\vertex_ai\gemini\vertex_and_google_ai_studio_gemini.py", line 2017, in completion
    response = client.post(url=url, headers=headers, json=data)  # type: ignore
  File "C:\Users\AngelicaChowdhury\anaconda3\envs\mas_family_exp\lib\site-packages\litellm\llms\custom_httpx\http_handler.py", line 780, in post
    raise e
  File "C:\Users\AngelicaChowdhury\anaconda3\envs\mas_family_exp\lib\site-packages\litellm\llms\custom_httpx\http_handler.py", line 762, in post
    response.raise_for_status()
  File "C:\Users\AngelicaChowdhury\anaconda3\envs\mas_family_exp\lib\site-packages\httpx\_models.py", line 829, in raise_for_status
    raise HTTPStatusError(message, request=request, response=self)
httpx.HTTPStatusError: Client error '429 Too Many Requests' for url 'https://generativelanguage.googleapis.com/v1beta/models/gemini-1.5-flash:generateContent?key=AIzaSyDDV3uUi1w4fhK0nvSAyU9oDYF7EvFKnfI'
For more information check: https://developer.mozilla.org/en-US/docs/Web/HTTP/Status/429

During handling of the above exception, another exception occurred:

Traceback (most recent call last):
  File "C:\Users\AngelicaChowdhury\anaconda3\envs\mas_family_exp\lib\site-packages\litellm\main.py", line 2781, in completion
    response = vertex_chat_completion.completion(  # type: ignore
  File "C:\Users\AngelicaChowdhury\anaconda3\envs\mas_family_exp\lib\site-packages\litellm\llms\vertex_ai\gemini\vertex_and_google_ai_studio_gemini.py", line 2021, in completion
    raise VertexAIError(
litellm.llms.vertex_ai.common_utils.VertexAIError: {
  "error": {
    "code": 429,
    "message": "You exceeded your current quota, please check your plan and billing details. For more information on this error, head to: https://ai.google.dev/gemini-api/docs/rate-limits.",
    "status": "RESOURCE_EXHAUSTED",
    "details": [
      {
        "@type": "type.googleapis.com/google.rpc.QuotaFailure",
        "violations": [
          {
            "quotaMetric": "generativelanguage.googleapis.com/generate_content_free_tier_requests",
            "quotaId": "GenerateRequestsPerDayPerProjectPerModel-FreeTier",
            "quotaDimensions": {
              "location": "global",
              "model": "gemini-1.5-flash"
            },
            "quotaValue": "50"
          }
        ]
      },
      {
        "@type": "type.googleapis.com/google.rpc.Help",
        "links": [
          {
            "description": "Learn more about Gemini API quotas",
            "url": "https://ai.google.dev/gemini-api/docs/rate-limits"
          }
        ]
      },
      {
        "@type": "type.googleapis.com/google.rpc.RetryInfo",
        "retryDelay": "17s"
      }
    ]
  }
}


During handling of the above exception, another exception occurred:

Traceback (most recent call last):
  File "C:\Users\AngelicaChowdhury\anaconda3\envs\mas_family_exp\lib\site-packages\crewai\agent.py", line 527, in _execute_with_timeout
    return future.result(timeout=timeout)
  File "C:\Users\AngelicaChowdhury\anaconda3\envs\mas_family_exp\lib\concurrent\futures\_base.py", line 458, in result
    return self.__get_result()
  File "C:\Users\AngelicaChowdhury\anaconda3\envs\mas_family_exp\lib\concurrent\futures\_base.py", line 403, in __get_result
    raise self._exception
  File "C:\Users\AngelicaChowdhury\anaconda3\envs\mas_family_exp\lib\concurrent\futures\thread.py", line 58, in run
    result = self.fn(*self.args, **self.kwargs)
  File "C:\Users\AngelicaChowdhury\anaconda3\envs\mas_family_exp\lib\site-packages\crewai\agent.py", line 547, in _execute_without_timeout
    return self.agent_executor.invoke(
  File "C:\Users\AngelicaChowdhury\anaconda3\envs\mas_family_exp\lib\site-packages\crewai\agents\crew_agent_executor.py", line 114, in invoke
    formatted_answer = self._invoke_loop()
  File "C:\Users\AngelicaChowdhury\anaconda3\envs\mas_family_exp\lib\site-packages\crewai\agents\crew_agent_executor.py", line 207, in _invoke_loop
    raise e
  File "C:\Users\AngelicaChowdhury\anaconda3\envs\mas_family_exp\lib\site-packages\crewai\agents\crew_agent_executor.py", line 153, in _invoke_loop
    answer = get_llm_response(
  File "C:\Users\AngelicaChowdhury\anaconda3\envs\mas_family_exp\lib\site-packages\crewai\utilities\agent_utils.py", line 161, in get_llm_response
    raise e
  File "C:\Users\AngelicaChowdhury\anaconda3\envs\mas_family_exp\lib\site-packages\crewai\utilities\agent_utils.py", line 154, in get_llm_response
    answer = llm.call(
  File "C:\Users\AngelicaChowdhury\anaconda3\envs\mas_family_exp\lib\site-packages\crewai\llm.py", line 1032, in call
    return self._handle_non_streaming_response(
  File "C:\Users\AngelicaChowdhury\anaconda3\envs\mas_family_exp\lib\site-packages\crewai\llm.py", line 813, in _handle_non_streaming_response
    response = litellm.completion(**params)
  File "C:\Users\AngelicaChowdhury\anaconda3\envs\mas_family_exp\lib\site-packages\litellm\utils.py", line 1342, in wrapper
    raise e
  File "C:\Users\AngelicaChowdhury\anaconda3\envs\mas_family_exp\lib\site-packages\litellm\utils.py", line 1217, in wrapper
    result = original_function(*args, **kwargs)
  File "C:\Users\AngelicaChowdhury\anaconda3\envs\mas_family_exp\lib\site-packages\litellm\main.py", line 3586, in completion
    raise exception_type(
  File "C:\Users\AngelicaChowdhury\anaconda3\envs\mas_family_exp\lib\site-packages\litellm\litellm_core_utils\exception_mapping_utils.py", line 2301, in exception_type
    raise e
  File "C:\Users\AngelicaChowdhury\anaconda3\envs\mas_family_exp\lib\site-packages\litellm\litellm_core_utils\exception_mapping_utils.py", line 1330, in exception_type
    raise RateLimitError(
litellm.exceptions.RateLimitError: litellm.RateLimitError: litellm.RateLimitError: VertexAIException - {
  "error": {
    "code": 429,
    "message": "You exceeded your current quota, please check your plan and billing details. For more information on this error, head to: https://ai.google.dev/gemini-api/docs/rate-limits.",
    "status": "RESOURCE_EXHAUSTED",
    "details": [
      {
        "@type": "type.googleapis.com/google.rpc.QuotaFailure",
        "violations": [
          {
            "quotaMetric": "generativelanguage.googleapis.com/generate_content_free_tier_requests",
            "quotaId": "GenerateRequestsPerDayPerProjectPerModel-FreeTier",
            "quotaDimensions": {
              "location": "global",
              "model": "gemini-1.5-flash"
            },
            "quotaValue": "50"
          }
        ]
      },
      {
        "@type": "type.googleapis.com/google.rpc.Help",
        "links": [
          {
            "description": "Learn more about Gemini API quotas",
            "url": "https://ai.google.dev/gemini-api/docs/rate-limits"
          }
        ]
      },
      {
        "@type": "type.googleapis.com/google.rpc.RetryInfo",
        "retryDelay": "17s"
      }
    ]
  }
}


During handling of the above exception, another exception occurred:

Traceback (most recent call last):
  File "C:\Users\AngelicaChowdhury\anaconda3\envs\mas_family_exp\lib\site-packages\crewai\agent.py", line 447, in execute_task
    result = self._execute_with_timeout(
  File "C:\Users\AngelicaChowdhury\anaconda3\envs\mas_family_exp\lib\site-packages\crewai\agent.py", line 535, in _execute_with_timeout
    raise RuntimeError(f"Task execution failed: {str(e)}")
RuntimeError: Task execution failed: litellm.RateLimitError: litellm.RateLimitError: VertexAIException - {
  "error": {
    "code": 429,
    "message": "You exceeded your current quota, please check your plan and billing details. For more information on this error, head to: https://ai.google.dev/gemini-api/docs/rate-limits.",
    "status": "RESOURCE_EXHAUSTED",
    "details": [
      {
        "@type": "type.googleapis.com/google.rpc.QuotaFailure",
        "violations": [
          {
            "quotaMetric": "generativelanguage.googleapis.com/generate_content_free_tier_requests",
            "quotaId": "GenerateRequestsPerDayPerProjectPerModel-FreeTier",
            "quotaDimensions": {
              "location": "global",
              "model": "gemini-1.5-flash"
            },
            "quotaValue": "50"
          }
        ]
      },
      {
        "@type": "type.googleapis.com/google.rpc.Help",
        "links": [
          {
            "description": "Learn more about Gemini API quotas",
            "url": "https://ai.google.dev/gemini-api/docs/rate-limits"
          }
        ]
      },
      {
        "@type": "type.googleapis.com/google.rpc.RetryInfo",
        "retryDelay": "17s"
      }
    ]
  }
}


During handling of the above exception, another exception occurred:

Traceback (most recent call last):
  File "C:\Users\AngelicaChowdhury\anaconda3\envs\mas_family_exp\lib\site-packages\crewai\agent.py", line 527, in _execute_with_timeout
    return future.result(timeout=timeout)
  File "C:\Users\AngelicaChowdhury\anaconda3\envs\mas_family_exp\lib\concurrent\futures\_base.py", line 458, in result
    return self.__get_result()
  File "C:\Users\AngelicaChowdhury\anaconda3\envs\mas_family_exp\lib\concurrent\futures\_base.py", line 403, in __get_result
    raise self._exception
  File "C:\Users\AngelicaChowdhury\anaconda3\envs\mas_family_exp\lib\concurrent\futures\thread.py", line 58, in run
    result = self.fn(*self.args, **self.kwargs)
  File "C:\Users\AngelicaChowdhury\anaconda3\envs\mas_family_exp\lib\site-packages\crewai\agent.py", line 547, in _execute_without_timeout
    return self.agent_executor.invoke(
  File "C:\Users\AngelicaChowdhury\anaconda3\envs\mas_family_exp\lib\site-packages\crewai\agents\crew_agent_executor.py", line 114, in invoke
    formatted_answer = self._invoke_loop()
  File "C:\Users\AngelicaChowdhury\anaconda3\envs\mas_family_exp\lib\site-packages\crewai\agents\crew_agent_executor.py", line 207, in _invoke_loop
    raise e
  File "C:\Users\AngelicaChowdhury\anaconda3\envs\mas_family_exp\lib\site-packages\crewai\agents\crew_agent_executor.py", line 153, in _invoke_loop
    answer = get_llm_response(
  File "C:\Users\AngelicaChowdhury\anaconda3\envs\mas_family_exp\lib\site-packages\crewai\utilities\agent_utils.py", line 161, in get_llm_response
    raise e
  File "C:\Users\AngelicaChowdhury\anaconda3\envs\mas_family_exp\lib\site-packages\crewai\utilities\agent_utils.py", line 154, in get_llm_response
    answer = llm.call(
  File "C:\Users\AngelicaChowdhury\anaconda3\envs\mas_family_exp\lib\site-packages\crewai\llm.py", line 1032, in call
    return self._handle_non_streaming_response(
  File "C:\Users\AngelicaChowdhury\anaconda3\envs\mas_family_exp\lib\site-packages\crewai\llm.py", line 813, in _handle_non_streaming_response
    response = litellm.completion(**params)
  File "C:\Users\AngelicaChowdhury\anaconda3\envs\mas_family_exp\lib\site-packages\litellm\utils.py", line 1342, in wrapper
    raise e
  File "C:\Users\AngelicaChowdhury\anaconda3\envs\mas_family_exp\lib\site-packages\litellm\utils.py", line 1217, in wrapper
    result = original_function(*args, **kwargs)
  File "C:\Users\AngelicaChowdhury\anaconda3\envs\mas_family_exp\lib\site-packages\litellm\main.py", line 3586, in completion
    raise exception_type(
  File "C:\Users\AngelicaChowdhury\anaconda3\envs\mas_family_exp\lib\site-packages\litellm\litellm_core_utils\exception_mapping_utils.py", line 2301, in exception_type
    raise e
  File "C:\Users\AngelicaChowdhury\anaconda3\envs\mas_family_exp\lib\site-packages\litellm\litellm_core_utils\exception_mapping_utils.py", line 1330, in exception_type
    raise RateLimitError(
litellm.exceptions.RateLimitError: litellm.RateLimitError: litellm.RateLimitError: VertexAIException - {
  "error": {
    "code": 429,
    "message": "You exceeded your current quota, please check your plan and billing details. For more information on this error, head to: https://ai.google.dev/gemini-api/docs/rate-limits.",
    "status": "RESOURCE_EXHAUSTED",
    "details": [
      {
        "@type": "type.googleapis.com/google.rpc.QuotaFailure",
        "violations": [
          {
            "quotaMetric": "generativelanguage.googleapis.com/generate_content_free_tier_requests",
            "quotaId": "GenerateRequestsPerDayPerProjectPerModel-FreeTier",
            "quotaDimensions": {
              "location": "global",
              "model": "gemini-1.5-flash"
            },
            "quotaValue": "50"
          }
        ]
      },
      {
        "@type": "type.googleapis.com/google.rpc.Help",
        "links": [
          {
            "description": "Learn more about Gemini API quotas",
            "url": "https://ai.google.dev/gemini-api/docs/rate-limits"
          }
        ]
      },
      {
        "@type": "type.googleapis.com/google.rpc.RetryInfo",
        "retryDelay": "16s"
      }
    ]
  }
}


During handling of the above exception, another exception occurred:

Traceback (most recent call last):
  File "C:\Users\AngelicaChowdhury\anaconda3\envs\mas_family_exp\lib\site-packages\crewai\agent.py", line 447, in execute_task
    result = self._execute_with_timeout(
  File "C:\Users\AngelicaChowdhury\anaconda3\envs\mas_family_exp\lib\site-packages\crewai\agent.py", line 535, in _execute_with_timeout
    raise RuntimeError(f"Task execution failed: {str(e)}")
RuntimeError: Task execution failed: litellm.RateLimitError: litellm.RateLimitError: VertexAIException - {
  "error": {
    "code": 429,
    "message": "You exceeded your current quota, please check your plan and billing details. For more information on this error, head to: https://ai.google.dev/gemini-api/docs/rate-limits.",
    "status": "RESOURCE_EXHAUSTED",
    "details": [
      {
        "@type": "type.googleapis.com/google.rpc.QuotaFailure",
        "violations": [
          {
            "quotaMetric": "generativelanguage.googleapis.com/generate_content_free_tier_requests",
            "quotaId": "GenerateRequestsPerDayPerProjectPerModel-FreeTier",
            "quotaDimensions": {
              "location": "global",
              "model": "gemini-1.5-flash"
            },
            "quotaValue": "50"
          }
        ]
      },
      {
        "@type": "type.googleapis.com/google.rpc.Help",
        "links": [
          {
            "description": "Learn more about Gemini API quotas",
            "url": "https://ai.google.dev/gemini-api/docs/rate-limits"
          }
        ]
      },
      {
        "@type": "type.googleapis.com/google.rpc.RetryInfo",
        "retryDelay": "16s"
      }
    ]
  }
}


During handling of the above exception, another exception occurred:

Traceback (most recent call last):
  File "C:\Users\AngelicaChowdhury\anaconda3\envs\mas_family_exp\lib\site-packages\crewai\agent.py", line 527, in _execute_with_timeout
    return future.result(timeout=timeout)
  File "C:\Users\AngelicaChowdhury\anaconda3\envs\mas_family_exp\lib\concurrent\futures\_base.py", line 458, in result
    return self.__get_result()
  File "C:\Users\AngelicaChowdhury\anaconda3\envs\mas_family_exp\lib\concurrent\futures\_base.py", line 403, in __get_result
    raise self._exception
  File "C:\Users\AngelicaChowdhury\anaconda3\envs\mas_family_exp\lib\concurrent\futures\thread.py", line 58, in run
    result = self.fn(*self.args, **self.kwargs)
  File "C:\Users\AngelicaChowdhury\anaconda3\envs\mas_family_exp\lib\site-packages\crewai\agent.py", line 547, in _execute_without_timeout
    return self.agent_executor.invoke(
  File "C:\Users\AngelicaChowdhury\anaconda3\envs\mas_family_exp\lib\site-packages\crewai\agents\crew_agent_executor.py", line 114, in invoke
    formatted_answer = self._invoke_loop()
  File "C:\Users\AngelicaChowdhury\anaconda3\envs\mas_family_exp\lib\site-packages\crewai\agents\crew_agent_executor.py", line 207, in _invoke_loop
    raise e
  File "C:\Users\AngelicaChowdhury\anaconda3\envs\mas_family_exp\lib\site-packages\crewai\agents\crew_agent_executor.py", line 153, in _invoke_loop
    answer = get_llm_response(
  File "C:\Users\AngelicaChowdhury\anaconda3\envs\mas_family_exp\lib\site-packages\crewai\utilities\agent_utils.py", line 161, in get_llm_response
    raise e
  File "C:\Users\AngelicaChowdhury\anaconda3\envs\mas_family_exp\lib\site-packages\crewai\utilities\agent_utils.py", line 154, in get_llm_response
    answer = llm.call(
  File "C:\Users\AngelicaChowdhury\anaconda3\envs\mas_family_exp\lib\site-packages\crewai\llm.py", line 1032, in call
    return self._handle_non_streaming_response(
  File "C:\Users\AngelicaChowdhury\anaconda3\envs\mas_family_exp\lib\site-packages\crewai\llm.py", line 813, in _handle_non_streaming_response
    response = litellm.completion(**params)
  File "C:\Users\AngelicaChowdhury\anaconda3\envs\mas_family_exp\lib\site-packages\litellm\utils.py", line 1342, in wrapper
    raise e
  File "C:\Users\AngelicaChowdhury\anaconda3\envs\mas_family_exp\lib\site-packages\litellm\utils.py", line 1217, in wrapper
    result = original_function(*args, **kwargs)
  File "C:\Users\AngelicaChowdhury\anaconda3\envs\mas_family_exp\lib\site-packages\litellm\main.py", line 3586, in completion
    raise exception_type(
  File "C:\Users\AngelicaChowdhury\anaconda3\envs\mas_family_exp\lib\site-packages\litellm\litellm_core_utils\exception_mapping_utils.py", line 2301, in exception_type
    raise e
  File "C:\Users\AngelicaChowdhury\anaconda3\envs\mas_family_exp\lib\site-packages\litellm\litellm_core_utils\exception_mapping_utils.py", line 1330, in exception_type
    raise RateLimitError(
litellm.exceptions.RateLimitError: litellm.RateLimitError: litellm.RateLimitError: VertexAIException - {
  "error": {
    "code": 429,
    "message": "You exceeded your current quota, please check your plan and billing details. For more information on this error, head to: https://ai.google.dev/gemini-api/docs/rate-limits.",
    "status": "RESOURCE_EXHAUSTED",
    "details": [
      {
        "@type": "type.googleapis.com/google.rpc.QuotaFailure",
        "violations": [
          {
            "quotaMetric": "generativelanguage.googleapis.com/generate_content_free_tier_requests",
            "quotaId": "GenerateRequestsPerDayPerProjectPerModel-FreeTier",
            "quotaDimensions": {
              "location": "global",
              "model": "gemini-1.5-flash"
            },
            "quotaValue": "50"
          }
        ]
      },
      {
        "@type": "type.googleapis.com/google.rpc.Help",
        "links": [
          {
            "description": "Learn more about Gemini API quotas",
            "url": "https://ai.google.dev/gemini-api/docs/rate-limits"
          }
        ]
      },
      {
        "@type": "type.googleapis.com/google.rpc.RetryInfo",
        "retryDelay": "15s"
      }
    ]
  }
}


During handling of the above exception, another exception occurred:

Traceback (most recent call last):
  File "C:\Projects\projects\mas_family_ic_exp\run_experiment.py", line 203, in main
    experiment.run_single_month(args.month)
  File "C:\Projects\projects\mas_family_ic_exp\src\experiment\main.py", line 1312, in run_single_month
    outcome = self.run_scenario(event)
  File "C:\Projects\projects\mas_family_ic_exp\src\experiment\main.py", line 506, in run_scenario
    result = self.crew.kickoff(inputs={"scenario": scenario_event.title})
  File "C:\Users\AngelicaChowdhury\anaconda3\envs\mas_family_exp\lib\site-packages\crewai\crew.py", line 662, in kickoff
    result = self._run_sequential_process()
  File "C:\Users\AngelicaChowdhury\anaconda3\envs\mas_family_exp\lib\site-packages\crewai\crew.py", line 776, in _run_sequential_process
    return self._execute_tasks(self.tasks)
  File "C:\Users\AngelicaChowdhury\anaconda3\envs\mas_family_exp\lib\site-packages\crewai\crew.py", line 879, in _execute_tasks
    task_output = task.execute_sync(
  File "C:\Users\AngelicaChowdhury\anaconda3\envs\mas_family_exp\lib\site-packages\crewai\task.py", line 381, in execute_sync
    return self._execute_core(agent, context, tools)
  File "C:\Users\AngelicaChowdhury\anaconda3\envs\mas_family_exp\lib\site-packages\crewai\task.py", line 529, in _execute_core
    raise e  # Re-raise the exception after emitting the event
  File "C:\Users\AngelicaChowdhury\anaconda3\envs\mas_family_exp\lib\site-packages\crewai\task.py", line 445, in _execute_core
    result = agent.execute_task(
  File "C:\Users\AngelicaChowdhury\anaconda3\envs\mas_family_exp\lib\site-packages\crewai\agent.py", line 487, in execute_task
    result = self.execute_task(task, context, tools)
  File "C:\Users\AngelicaChowdhury\anaconda3\envs\mas_family_exp\lib\site-packages\crewai\agent.py", line 487, in execute_task
    result = self.execute_task(task, context, tools)
  File "C:\Users\AngelicaChowdhury\anaconda3\envs\mas_family_exp\lib\site-packages\crewai\agent.py", line 486, in execute_task
    raise e
  File "C:\Users\AngelicaChowdhury\anaconda3\envs\mas_family_exp\lib\site-packages\crewai\agent.py", line 447, in execute_task
    result = self._execute_with_timeout(
  File "C:\Users\AngelicaChowdhury\anaconda3\envs\mas_family_exp\lib\site-packages\crewai\agent.py", line 535, in _execute_with_timeout
    raise RuntimeError(f"Task execution failed: {str(e)}")
RuntimeError: Task execution failed: litellm.RateLimitError: litellm.RateLimitError: VertexAIException - {
  "error": {
    "code": 429,
    "message": "You exceeded your current quota, please check your plan and billing details. For more information on this error, head to: https://ai.google.dev/gemini-api/docs/rate-limits.",
    "status": "RESOURCE_EXHAUSTED",
    "details": [
      {
        "@type": "type.googleapis.com/google.rpc.QuotaFailure",
        "violations": [
          {
            "quotaMetric": "generativelanguage.googleapis.com/generate_content_free_tier_requests",
            "quotaId": "GenerateRequestsPerDayPerProjectPerModel-FreeTier",
            "quotaDimensions": {
              "location": "global",
              "model": "gemini-1.5-flash"
            },
            "quotaValue": "50"
          }
        ]
      },
      {
        "@type": "type.googleapis.com/google.rpc.Help",
        "links": [
          {
            "description": "Learn more about Gemini API quotas",
            "url": "https://ai.google.dev/gemini-api/docs/rate-limits"
          }
        ]
      },
      {
        "@type": "type.googleapis.com/google.rpc.RetryInfo",
        "retryDelay": "15s"
      }
    ]
  }
}


